Workbook
Name _edn4: #REF!
Name _edn3: #REF!
Name _ednref2: #REF!
Name _ednref3: #REF!
Name _ednref1: #REF!
Name _edn2: #REF!
Name _ednref4: #REF!
Name egresoc2: #REF!
Name _edn1: #REF!
Name TIPO: #REF!
Name egresoc2: #REF!
Name egresoc2: #REF!
Name egresoc2: #REF!
Name TIPO: #REF!

Sheet INSTITUCION
A1: *Se debe presentar 1 (un) formulario por cada proyecto solicitado. *La institución deberá tener vigente su inscripción al SIPAF al momento de la presentación del proyecto.
A3: 1. INSTITUCIÓN (ES) QUE PRESENTA(N) LA PROPUESTA:
A4: INSTITUCIÓN:
A5: CUIT:
A6: DOMICILIO:
A7: LOCALIDAD: | H7: CP:
A8: TELÉFONO: | E8: MAIL INSTITUCIONAL:
A10: 2. COORDINADOR/A DEL PROYECTO (Nexo con la Dirección de Capacitación y Formación Laboral):
A11: NOMBRE COMPLETO:
A12: DNI: | F12: Nº DE REGISTRO:
A13: TELÉFONO: | F13: MAIL:
A14: HORARIO:
A15: Descripción de su función en la Institución que presenta:
A18: 3. ¿Ha trabajado con programas de empleo y capacitación de la provincia?
C20: Sí.
C21: No.
B23: ¿Cuáles?:
C24: Redes / Santa Fe Capacita.
C25: Nexo Oportunidad / Prácticas Laborales.
C26: Mi Primer Empleo.
C27: Nueva Oportunidad / Santa Fe Más.
A29: 4. Describir brevemente qué actividades realizan en la institución y qué se aportará para el desarrollo de la propuesta (Ejemplo: Instalaciones, Maquinarias). Acompañar fotos de las instalaciones:

Sheet FUNDAMENTACION
A1: FUNDAMENTACIÓN DEL PROYECTO
A2: 1. Denominación del proyecto:
A5: 2.1. Necesidad de implementación de la propuesta / vinculación con necesidades productivas locales y regionales:
A8: 2.2. Cantidad de habitantes que tiene la Localidad:
A12: 3. Empresas demandantes de mano de obra relacionada a la capacitación:
A13: *COMPLETAR: NOMBRE DE LA EMPRESA/COMERCIO - ACTIVIDAD - CONTACTO - MAIL - TELÉFONO - DIRECCIÓN
A21: 4. ¿A qué población está orientada la propuesta?
C23: Población desocupada en general.
C24: Población ocupada con necesidad de recalificación.
C25: Personas con discapacidad.
C26: Población penitenciaria / pospenitenciaria.
C27: Colectivo LGBT+.
C28: Pueblos originarios.
C29: Otras poblaciones:
A32: 5. Link de Inscripción. (solo para proyectos A, B).
A33: La inscripción a los cursos debe hacerse on line, a fin de agilizar el trámite en el caso de que sea aprobado por la Comisión Evaluadora, le solicitamos nos envíe un link por cada propuesta donde los interesados podrán inscribirse. Para la creación del formulario de inscripción, le sugerimos utilice un google forms (forms.google.com) a tal efecto. Desde este Ministerio haremos publicaciones para promocionar el dictado del curso, por lo que nos es imprescindible contar con dicha información. Si el curso ha sido presentado teniendo en cuenta una población específica y por lo tanto la inscripción no se encontrará abierta a la comunidad, le solicitamos nos lo informe con una explicación que justifique tal situación.
A35: 6. Tipo de proyecto (A, B, F). Indique la opción que corresponda:
C37: TIPO A. Desarrollo formativo: Proyectos cuyo objetivo sea el dictado de un curso de capacitación para el desarrollo formativo ocupacional de los beneficiarios. Duración mínima de 80 hs y máxima de 160 hs. (Aprendizaje de oficio. Ejemplo: "auxiliar de panadería").
C41: Presencial.
C42: Bimodal.
C43: Virtual.
C46: TIPO B. Competencias laborales: Proyectos cuyo objetivo sea el dictado de una capacitación para la adquisición por parte de los beneficiarios, de competencias laborales específicas o la actualización de sus competencias para el mundo del trabajo. Duración máxima 79 hs. (Adquisición de competencias específicas. Ejemplo: "elaboración de panificación navideña").
C50: Presencial.
C51: Bimodal.
C52: Virtual.
A54: Los proyectos de DESARROLLO FORMATIVO y COMPETENCIAS LABORALES que requieran la compra de bienes durables, deberán solicitar su financiamiento a través de FORTALECIMIENTO INSTITUCIONAL.
C56: TIPO F. Fortalecimiento institucional (Compra de bienes durables para ejecutar el curso): Tienen por objeto el otorgamiento a las instituciones ejecutoras, de aportes no reintegrables para la optimización y acondicionamiento de entornos formativos, compra de herramientas, bienes durables y/o indumentaria para el trabajo. La institución deberá tener al menos un proyecto de capacitación aprobado o cuya aprobación se tramite en forma concomitante. Asimismo, debe informar el detalle de los aportes requeridos acompañando de los presupuestos de los proveedores/ prestadores.

Sheet CURSO
A1: PROYECTOS DE DESARROLLO FORMATIVO / COMPETENCIAS LABORALES
A2: Tipo A y B
A3: Datos del Proyecto de Capacitación Laboral
A5: 1. Requisitos de ingreso de los beneficiarios según proyecto (describirlos). (Ej. Edad, formación).
A8: 2. Perfil de egreso. Describa qué va a saber hacer la persona que finalice esta formación.
A11: 3. Unidades / módulos de dictado.
A12: (ir a pestaña "Diseño Curricular")
A14: 4. Características de dictado. (Sólo para cursos presenciales / bimodales) - (Recordar que si se trata de un espacio ajeno a la institución debe presentar nota de cesión firmada).
A15: Teoría
A16: Carga horaria estimada teoría: | D16: 0
A17: Nombre del lugar de dictado:
A18: Dirección /Localidad:
A20: Práctica
A21: Carga horaria estimada práctica: | D21: 0
A22: Nombre del lugar de dictado:
A23: Dirección/Localidad:
A25: 5. Modalidad de dictado. (Sólo para cursos virtuales y/o bimodales).
A26: Describir brevemente el encuadre de dictado (Plataforma. Sincrónico / Asincrónico. Videos).
A28: Carga horaria estimada: | D28: 0
A30: 6. Días y horarios de dictado.
A33: Cantidad de Vacantes: | D33: Carga Horaria Total: | F33: =D16+D21+D28 -> 0
A36: 7. Equipo pedagógico. | H36: DOCENTE
A37: Equipo pedagógico, roles posibles: -Docente. -Tutor: sólo para propuestas virtuales. -Acompañante: sólo para grupos priorizados. -Intérprete en lenguaje de señas. | H37: TUTOR
A38: Rol: | E38: Nº Registro: | H38: ACOMPAÑANTE
A39: Apellido y Nombre: | E39: DNI: | H39: INTÉRPRETE EN LENGUAJE DE SEÑAS
A40: Teléfono:
A41: Dirección:
A42: Mail:
A43: Título/Certificación:
A44: Observaciones:
A45: Carga horaria: | C45: 0 | D45: hs. | E45: Costo por hora: | F45: 0
A47: Rol: | E47: Nº Registro:
A48: Apellido y Nombre: | E48: DNI:
A49: Teléfono:
A50: Dirección:
A51: Mail:
A52: Título/Certificación:
A53: Observaciones:
A54: Carga horaria: | C54: 0 | D54: hs. | E54: Costo por hora: | F54: 0
A56: Rol: | E56: Nº Registro: | H56: Tutor
...

Sheet DISEÑO CURRICULAR
A1: Unidades / módulos de dictado:

Sheet PRESUPUESTO (A-B)
A1: PRESUPUESTO PROYECTOS TIPO "A / B"
A2: DESCRIPCIÓN DE LOS RECURSOS SOLICITADOS
A4: 1. BIENES NO DURABLES.
A5: *Sólo se financian bienes cuya vida útil se agota junto con el proyecto.
A6: ARTÍCULO | B6: CANTIDAD | C6: DETALLE (tipo y modelo) | D6: PRECIO UNITARIO | E6: TOTAL
A7: *DESTORNILLADOR | B7: 5 | C7: PUNTA PLANA | D7: 50 | E7: =IF(B7="","",IF(B7="","",B7*D7)) -> 250
E8: =IF(B8="","",IF(B8="","",B8*D8))
E9: =IF(B9="","",IF(B9="","",B9*D9))
E10: =IF(B10="","",IF(B10="","",B10*D10))
E11: =IF(B11="","",IF(B11="","",B11*D11))
E12: =IF(B12="","",IF(B12="","",B12*D12))
E13: =IF(B13="","",IF(B13="","",B13*D13))
E14: =IF(B14="","",IF(B14="","",B14*D14))
E15: =IF(B15="","",IF(B15="","",B15*D15))
E16: =IF(B16="","",IF(B16="","",B16*D16))
E17: =IF(B17="","",IF(B17="","",B17*D17))
E18: =IF(B18="","",IF(B18="","",B18*D18))
E19: =IF(B19="","",IF(B19="","",B19*D19))
... E32: =IF(B32="","",IF(B32="","",B32*D32))
A33: TOTAL SOLICITADO EN BIENES NO DURABLES | E33: =SUM(E8:E32) -> 0
A35: 2. ELEMENTOS DE SEGURIDAD.
A36: *Sólo se financian bienes cuya vida útil se agota junto con el proyecto.
A37: ARTÍCULO | B37: CANTIDAD | C37: DETALLE (tipo y modelo) | D37: PRECIO UNITARIO | E37: TOTAL
A38: *GUANTES | B38: 100 | C38: DE LATEX DESCARTABLES | D38: 5 | E38: =IF(B38="","",IF(D38="","",D38*B38)) -> 500
E39: =IF(B39="","",IF(D39="","",D39*B39))
E40: =IF(B40="","",IF(D40="","",D40*B40))
E41: =IF(B41="","",IF(D41="","",D41*B41))
E42: =IF(B42="","",IF(D42="","",D42*B42))
E43: =IF(B43="","",IF(D43="","",D43*B43))
E44: =IF(B44="","",IF(D44="","",D44*B44))
E45: =IF(B45="","",IF(D45="","",D45*B45))
E46: =IF(B46="","",IF(D46="","",D46*B46))
E47: =IF(B47="","",IF(D47="","",D47*B47))
E48: =IF(B48="","",IF(D48="","",D48*B48))
E49: =IF(B49="","",IF(D49="","",D49*B49))
E50: =IF(B50="","",IF(D50="","",D50*B50))
A51: TOTAL SOLICITADO EN ELEMENTOS DE SEGURIDAD | E51: =SUM(E39:E50) -> 0
A53: 3. MATERIAL DIDÁCTICO.
A54: ARTÍCULO | B54: CANTIDAD | C54: DETALLE (tipo y modelo) | D54: PRECIO UNITARIO | E54: TOTAL
A55: *CUADERNILLOS | B55: 20 | C55: A4, 60 HOJAS RAYADAS | D55: 15 | E55: =IF(B55="","",IF(D55="","",D55*B55)) -> 300
...

Sheet PRESUPUESTO (F)
A1: PRESUPUESTO PROYECTOS TIPO "F"
A2: DESCRIPCIÓN DE LOS BIENES DURABLES
A3: *Sólo se financian bienes para la optimización y acondicionamiento de entornos formativos, compra de herramientas, bienes durables y/o indumentaria para el trabajo. *LA INSTITUCIÓN deberá mantener los bienes en su poder por el plazo de CINCO AÑOS. *Se debe acompañar un presupuesto de proveedor por cada bien solicitado.
A5: RUBRO | B5: ARTÍCULO | C5: CANTIDAD | D5: DETALLE (tipo y modelo) | E5: PRECIO UNITARIO | F5: PRESUPUESTO TOTAL
F6: =IF(C6="","",IF(C6="","",C6*E6)) | H6: HERRAMIENTAS
F7: =IF(C7="","",IF(C7="","",C7*E7)) | H7: BIENES DURABLES
F8: =IF(C8="","",IF(C8="","",C8*E8)) | H8: INDUMENTARIA
F9: =IF(C9="","",IF(C9="","",C9*E9))
F10: =IF(C10="","",IF(C10="","",C10*E10))
F11: =IF(C11="","",IF(C11="","",C11*E11))
F12: =IF(C12="","",IF(C12="","",C12*E12))
F13: =IF(C13="","",IF(C13="","",C13*E13))
F14: =IF(C14="","",IF(C14="","",C14*E14))
F15: =IF(C15="","",IF(C15="","",C15*E15))
F16: =IF(C16="","",IF(C16="","",C16*E16))
F17: =IF(C17="","",IF(C17="","",C17*E17))
F18: =IF(C18="","",IF(C18="","",C18*E18))
F19: =IF(C19="","",IF(C19="","",C19*E19))
F20: =IF(C20="","",IF(C20="","",C20*E20))
... F24: =IF(C24="","",IF(C24="","",C24*E24))
A25: TOTAL SOLICITADO | F25: =SUM(F6:F24) -> 0

Sheet RESUMEN PRESUPUESTO
A2: PRESUPUESTO DEL CURSO - RESUMEN DE COSTOS DEL PROYECTO
A3: INSTITUCIÓN: | B3: =INSTITUCION!C4
A4: NOMBRE DEL PROYECTO: | B4: =FUNDAMENTACION!A3
A6: FINANCIACIÓN TIPOS | B6: INSUMOS / BIENES NO DURABLES | C6: ELEMENTOS DE SEGURIDAD | D6: MATERIAL DIDACTICO | E6: HONORARIOS DOCENTES | F6: BIENES DURABLES | G6: SUBTOTAL
A8: A / B | B8: ='PRESUPUESTO (A-B)'!E33 -> 0 | C8: ='PRESUPUESTO (A-B)'!E51 -> 0 | D8: ='PRESUPUESTO (A-B)'!E67 -> 0 | E8: ='PRESUPUESTO (A-B)'!E75 -> 0 | F8: - | G8: =SUM(B8:E8) -> 0
A10: F | B10: - | C10: - | D10: - | E10: - | F10: ='PRESUPUESTO (F)'!F25 -> 0 | G10: ='PRESUPUESTO (F)'!F25 -> 0
A11: MONTO TOTAL PROYECTO | G11: =G8+G10 -> 0
A12: Declaro conocer los requisitos de presentación de proyectos, la forma de financiamiento y certifico que todos los datos incorporados a este formularios son ciertos. Otórgase facultades a la persona designada coordinador del curso como representante de esta Institución frente al Ministerio de Trabajo, Empleo y Seguridad Social de la Provincia de Santa Fe, autorizándolo a realizar las gestiones administrativas pertinentes a la ejecución del proyecto aprobado por la Comisión Evaluadora.-
A18: FECHA, FIRMA Y SELLO DEL RESPONSABLE DE LA INSTITUCIÓN
A22: IMPORTANTE:
A23: 1. El formulario debe estar completo, firmado y sellado por el responsable de la institución. 2. La institución deberá estar inscripta en el SIPAF y sus datos actualizados. 3. El Ministerio de Trabajo, Empleo y Seguridad Social de la Provincia, transferirá los fondos aprobados una vez que la Institución haya cumplido con la totalidad de los requisitos exigidos.

Sheet NOTA CESION
E4: LUGAR | F4: , | G4: DÍA | H4: de | I4: MES | J4: de | K4: 2023
A9: A la Comisión Evaluadora
A10: PROGRAMA SANTA FE CAPACITA
A12: Por medio de la presente, nos dirigimos a Usted
A13: con el objeto de informar que la Institución:
A14: cede sus instalaciones ubicadas en calle:
B15: para el dictado del curso denominado:
A16: =FUNDAMENTACION!A3
A17: presentado por la Institución:
A18: =INSTITUCION!C4
A21: Sin otro particular, saludamos a Uds. muy atte.
B24: Institución / Organismo que cede las instalaciones | E24: Firma:
E26: Aclaración:
E27: Cargo:

Sheet CARATULA
E2: N° DE PROYECTO:
E3: APROBADO | F3: RECHAZADO
A5: SANTA FE CAPACITA
A6: ˗ 2024 ˗
A7: APRENDER PRODUCCIÓN Y TRABAJO
A9: FORMULARIO PARA LA PRESENTACIÓN DE
A10: PROYECTOS
A14: NOMBRE DE LA INSTITUCIÓN:
A15: =INSTITUCION!C4
A17: NOMBRE DEL PROYECTO:
A18: =FUNDAMENTACION!A3
B20: Tipo | C20: Presencial | D20: Virtual | E20: Bimodal
A21: A | B21: =FUNDAMENTACION!B37 | C21: =FUNDAMENTACION!B41 | D21: =FUNDAMENTACION!B43 | E21: =FUNDAMENTACION!B42
A22: B | B22: =FUNDAMENTACION!B46 | C22: =FUNDAMENTACION!B50 | D22: =FUNDAMENTACION!B52 | E22: =FUNDAMENTACION!B51
A23: F | B23: =FUNDAMENTACION!B56
A25: DIRECCIÓN/ LOCALIDAD (Teoría) | B25: =CURSO!C18
A26: DIRECCIÓN/ LOCALIDAD (Práctica) | B26: =CURSO!C23
A28: CANTIDAD DE VACANTES | B28: =CURSO!C33
A30: CARGA HORARIA TOTAL | B30: =CURSO!F33 -> 0
A32: PRESUPUESTO A / B | B32: ='RESUMEN PRESUPUESTO'!G8 -> 0
A34: PRESUPUESTO F | B34: ='RESUMEN PRESUPUESTO'!F10 -> 0
A36: PRESUPUESTO TOTAL | B36: ='RESUMEN PRESUPUESTO'!G11 -> 0
